<sdf version='1.6'>
  <world name='default'>
    <light name='sun' type='directional'>
      <cast_shadows>1</cast_shadows>
      <pose frame=''>0 0 10 0 -0 0</pose>
      <diffuse>0.8 0.8 0.8 1</diffuse>
      <specular>0.2 0.2 0.2 1</specular>
      <attenuation>
        <range>1000</range>
        <constant>0.9</constant>
        <linear>0.01</linear>
        <quadratic>0.001</quadratic>
      </attenuation>
      <direction>-0.5 0.1 -0.9</direction>
    </light>
    <model name='ground_plane'>
      <static>1</static>
      <link name='link'>
        <collision name='collision'>
          <geometry>
            <plane>
              <normal>0 0 1</normal>
              <size>100 100</size>
            </plane>
          </geometry>
          <surface>
            <friction>
              <ode>
                <mu>100</mu>
                <mu2>50</mu2>
              </ode>
              <torsional>
                <ode/>
              </torsional>
            </friction>
            <contact>
              <ode/>
            </contact>
            <bounce/>
          </surface>
          <max_contacts>10</max_contacts>
        </collision>
        <visual name='visual'>
          <cast_shadows>0</cast_shadows>
          <geometry>
            <plane>
              <normal>0 0 1</normal>
              <size>100 100</size>
            </plane>
          </geometry>
          <material>
            <script>
              <uri>file://media/materials/scripts/gazebo.material</uri>
              <name>Gazebo/Grey</name>
            </script>
          </material>
        </visual>
        <self_collide>0</self_collide>
        <enable_wind>0</enable_wind>
        <kinematic>0</kinematic>
      </link>
    </model>
    <gravity>0 0 -9.8</gravity>
    <magnetic_field>6e-06 2.3e-05 -4.2e-05</magnetic_field>
    <atmosphere type='adiabatic'/>
    <physics name='default_physics' default='0' type='ode'>
      <max_step_size>0.001</max_step_size>
      <real_time_factor>1</real_time_factor>
      <real_time_update_rate>1000</real_time_update_rate>
    </physics>
    <scene>
      <ambient>0.4 0.4 0.4 1</ambient>
      <background>0.7 0.7 0.7 1</background>
      <shadows>1</shadows>
    </scene>
    <audio>
      <device>default</device>
    </audio>
    <wind/>
    <spherical_coordinates>
      <surface_model>EARTH_WGS84</surface_model>
      <latitude_deg>0</latitude_deg>
      <longitude_deg>0</longitude_deg>
      <elevation>0</elevation>
      <heading_deg>0</heading_deg>
    </spherical_coordinates>
    <model name='turtle_ar'>
      <link name='base_footprint'>
        <pose frame=''>0 0 0 0 -0 0</pose>
        <inertial>
          <pose frame=''>-0.013451 0 0.038321 0 -0 0</pose>
          <mass>1.04474</mass>
          <inertia>
            <ixx>0.00784713</ixx>
            <ixy>-1.22941e-05</ixy>
            <ixz>0.00126278</ixz>
            <iyy>0.00871457</iyy>
            <iyz>-5.01209e-06</iyz>
            <izz>0.00506694</izz>
          </inertia>
        </inertial>
        <collision name='base_footprint_fixed_joint_lump__base_link_collision'>
          <pose frame=''>-0.032 0 0.08 0 -0 0</pose>
          <geometry>
            <box>
              <size>0.14 0.14 0.143</size>
            </box>
          </geometry>
          <surface>
            <contact>
              <ode/>
            </contact>
            <friction>
              <ode/>
              <torsional>
                <ode/>
              </torsional>
            </friction>
            <bounce/>
          </surface>
          <max_contacts>10</max_contacts>
        </collision>
        <collision name='base_footprint_fixed_joint_lump__ar_link_collision_1'>
          <pose frame=''>-0.1 0 0.11 0 -0 0</pose>
          <geometry>
            <mesh>
              <scale>1 1 1</scale>
              <uri>/home/kketan20/Workspaces/rsp_project/src/rsp_project/turtle_Project_simulation/turtlebot_description/meshes/ar.dae</uri>
            </mesh>
          </geometry>
          <surface>
            <contact>
              <ode>
                <kp>10</kp>
                <kd>10</kd>
              </ode>
            </contact>
            <friction>
              <ode>
                <mu>0.1</mu>
                <mu2>0.1</mu2>
                <fdir1>1 0 0</fdir1>
              </ode>
              <torsional>
                <ode/>
              </torsional>
            </friction>
            <bounce/>
          </surface>
          <max_contacts>10</max_contacts>
        </collision>
        <collision name='base_footprint_fixed_joint_lump__caster_back_link_collision_2'>
          <pose frame=''>-0.081 1e-06 0.005 -1.57 0 0</pose>
          <geometry>
            <box>
              <size>0.03 0.009 0.02</size>
            </box>
          </geometry>
          <surface>
            <contact>
              <ode>
                <kp>1e+06</kp>
                <kd>100</kd>
                <max_vel>1</max_vel>
                <min_depth>0.001</min_depth>
              </ode>
            </contact>
            <friction>
              <ode>
                <mu>0.1</mu>
                <mu2>0.1</mu2>
              </ode>
              <torsional>
                <ode/>
              </torsional>
            </friction>
            <bounce/>
          </surface>
          <max_contacts>10</max_contacts>
        </collision>
        <collision name='base_footprint_fixed_joint_lump__base_scan_collision_3'>
          <pose frame=''>-0.017 0 0.1755 0 -0 0</pose>
          <geometry>
            <cylinder>
              <length>0.0315</length>
              <radius>0.055</radius>
            </cylinder>
          </geometry>
          <surface>
            <contact>
              <ode/>
            </contact>
            <friction>
              <ode/>
              <torsional>
                <ode/>
              </torsional>
            </friction>
            <bounce/>
          </surface>
          <max_contacts>10</max_contacts>
        </collision>
        <visual name='base_footprint_fixed_joint_lump__base_link_visual'>
          <pose frame=''>-0.032 0 0.01 0 -0 0</pose>
          <geometry>
            <mesh>
              <scale>0.001 0.001 0.001</scale>
              <uri>/home/kketan20/Workspaces/rsp_project/src/rsp_project/turtlebot3/turtlebot3_description/meshes/bases/burger_base.stl</uri>
            </mesh>
          </geometry>
          <material>
            <script>
              <name>Gazebo/DarkGrey</name>
              <uri>file://media/materials/scripts/gazebo.material</uri>
            </script>
          </material>
        </visual>
        <visual name='base_footprint_fixed_joint_lump__ar_link_visual_1'>
          <pose frame=''>-0.1 0 0.11 3.14159 1.57079 -0.001593</pose>
          <geometry>
            <mesh>
              <scale>1 1 1</scale>
              <uri>/home/kketan20/Workspaces/rsp_project/src/rsp_project/turtle_Project_simulation/turtlebot_description/meshes/ar.dae</uri>
            </mesh>
          </geometry>
          <material>
            <script>
              <uri>__default__</uri>
              <name>__default__</name>
            </script>
          </material>
        </visual>
        <visual name='base_footprint_fixed_joint_lump__base_scan_visual_2'>
          <pose frame=''>-0.032 0 0.182 0 -0 0</pose>
          <geometry>
            <mesh>
              <scale>0.001 0.001 0.001</scale>
              <uri>/home/kketan20/Workspaces/rsp_project/src/rsp_project/turtlebot3/turtlebot3_description/meshes/sensors/lds.stl</uri>
            </mesh>
          </geometry>
          <material>
            <script>
              <name>Gazebo/FlatBlack</name>
              <uri>file://media/materials/scripts/gazebo.material</uri>
            </script>
          </material>
        </visual>
        <velocity_decay/>
        <velocity_decay/>
        <velocity_decay/>
        <velocity_decay/>
        <sensor name='imu' type='imu'>
          <always_on>1</always_on>
          <visualize>0</visualize>
          <pose frame=''>-0.032 0 0.078 0 -0 0</pose>
          <imu/>
        </sensor>
        <gravity>1</gravity>
        <velocity_decay/>
        <sensor name='lds_lfcd_sensor' type='ray'>
          <visualize>0</visualize>
          <update_rate>5</update_rate>
          <ray>
            <scan>
              <horizontal>
                <samples>360</samples>
                <resolution>1</resolution>
                <min_angle>0</min_angle>
                <max_angle>6.28319</max_angle>
              </horizontal>
              <vertical>
                <samples>1</samples>
                <min_angle>0</min_angle>
                <max_angle>0</max_angle>
              </vertical>
            </scan>
            <range>
              <min>0.12</min>
              <max>3.5</max>
              <resolution>0.015</resolution>
            </range>
            <noise>
              <type>gaussian</type>
              <mean>0</mean>
              <stddev>0.01</stddev>
            </noise>
          </ray>
          <plugin name='gazebo_ros_lds_lfcd_controller' filename='libgazebo_ros_laser.so'>
            <topicName>scan</topicName>
            <frameName>base_scan</frameName>
            <robotNamespace>/turtle_ar/</robotNamespace>
          </plugin>
          <pose frame=''>-0.032 0 0.182 0 -0 0</pose>
        </sensor>
        <self_collide>0</self_collide>
        <enable_wind>0</enable_wind>
        <kinematic>0</kinematic>
      </link>
      <link name='wheel_left_link'>
        <pose frame=''>0 0.08 0.033 -1.57 0 0</pose>
        <inertial>
          <pose frame=''>0 0 0 0 -0 0</pose>
          <mass>0.0284989</mass>
          <inertia>
            <ixx>1.11756e-05</ixx>
            <ixy>-4.23698e-11</ixy>
            <ixz>-5.93817e-09</ixz>
            <iyy>1.11924e-05</iyy>
            <iyz>-1.44001e-11</iyz>
            <izz>2.07126e-05</izz>
          </inertia>
        </inertial>
        <collision name='wheel_left_link_collision'>
          <pose frame=''>0 0 0 0 -0 0</pose>
          <geometry>
            <cylinder>
              <length>0.018</length>
              <radius>0.033</radius>
            </cylinder>
          </geometry>
          <surface>
            <contact>
              <ode>
                <kp>500000</kp>
                <kd>10</kd>
                <max_vel>0.1</max_vel>
                <min_depth>0.001</min_depth>
              </ode>
            </contact>
            <friction>
              <ode>
                <mu>0.1</mu>
                <mu2>0.1</mu2>
                <fdir1>1 0 0</fdir1>
              </ode>
              <torsional>
                <ode/>
              </torsional>
            </friction>
            <bounce/>
          </surface>
          <max_contacts>10</max_contacts>
        </collision>
        <visual name='wheel_left_link_visual'>
          <pose frame=''>0 0 0 1.57 -0 0</pose>
          <geometry>
            <mesh>
              <scale>0.001 0.001 0.001</scale>
              <uri>/home/kketan20/Workspaces/rsp_project/src/rsp_project/turtlebot3/turtlebot3_description/meshes/wheels/left_tire.stl</uri>
            </mesh>
          </geometry>
          <material>
            <script>
              <name>Gazebo/FlatBlack</name>
              <uri>file://media/materials/scripts/gazebo.material</uri>
            </script>
          </material>
        </visual>
        <gravity>1</gravity>
        <velocity_decay/>
        <self_collide>0</self_collide>
        <enable_wind>0</enable_wind>
        <kinematic>0</kinematic>
      </link>
      <joint name='wheel_left_joint' type='revolute'>
        <child>wheel_left_link</child>
        <parent>base_footprint</parent>
        <axis>
          <xyz>0 1 0.000796</xyz>
          <limit>
            <lower>-1e+16</lower>
            <upper>1e+16</upper>
          </limit>
          <dynamics>
            <spring_reference>0</spring_reference>
            <spring_stiffness>0</spring_stiffness>
          </dynamics>
          <use_parent_model_frame>1</use_parent_model_frame>
        </axis>
      </joint>
      <link name='wheel_right_link'>
        <pose frame=''>0 -0.08 0.033 -1.57 0 0</pose>
        <inertial>
          <pose frame=''>0 0 0 0 -0 0</pose>
          <mass>0.0284989</mass>
          <inertia>
            <ixx>1.11756e-05</ixx>
            <ixy>-4.23698e-11</ixy>
            <ixz>-5.93817e-09</ixz>
            <iyy>1.11924e-05</iyy>
            <iyz>-1.44001e-11</iyz>
            <izz>2.07126e-05</izz>
          </inertia>
        </inertial>
        <collision name='wheel_right_link_collision'>
          <pose frame=''>0 0 0 0 -0 0</pose>
          <geometry>
            <cylinder>
              <length>0.018</length>
              <radius>0.033</radius>
            </cylinder>
          </geometry>
          <surface>
            <contact>
              <ode>
                <kp>500000</kp>
                <kd>10</kd>
                <max_vel>0.1</max_vel>
                <min_depth>0.001</min_depth>
              </ode>
            </contact>
            <friction>
              <ode>
                <mu>0.1</mu>
                <mu2>0.1</mu2>
                <fdir1>1 0 0</fdir1>
              </ode>
              <torsional>
                <ode/>
              </torsional>
            </friction>
            <bounce/>
          </surface>
          <max_contacts>10</max_contacts>
        </collision>
        <visual name='wheel_right_link_visual'>
          <pose frame=''>0 0 0 1.57 -0 0</pose>
          <geometry>
            <mesh>
              <scale>0.001 0.001 0.001</scale>
              <uri>/home/kketan20/Workspaces/rsp_project/src/rsp_project/turtlebot3/turtlebot3_description/meshes/wheels/right_tire.stl</uri>
            </mesh>
          </geometry>
          <material>
            <script>
              <name>Gazebo/FlatBlack</name>
              <uri>file://media/materials/scripts/gazebo.material</uri>
            </script>
          </material>
        </visual>
        <gravity>1</gravity>
        <velocity_decay/>
        <self_collide>0</self_collide>
        <enable_wind>0</enable_wind>
        <kinematic>0</kinematic>
      </link>
      <joint name='wheel_right_joint' type='revolute'>
        <child>wheel_right_link</child>
        <parent>base_footprint</parent>
        <axis>
          <xyz>0 1 0.000796</xyz>
          <limit>
            <lower>-1e+16</lower>
            <upper>1e+16</upper>
          </limit>
          <dynamics>
            <spring_reference>0</spring_reference>
            <spring_stiffness>0</spring_stiffness>
          </dynamics>
          <use_parent_model_frame>1</use_parent_model_frame>
        </axis>
      </joint>
      <plugin name='turtlebot3_burger_controller' filename='libgazebo_ros_diff_drive.so'>
        <commandTopic>cmd_vel</commandTopic>
        <odometryTopic>odom</odometryTopic>
        <odometryFrame>odom</odometryFrame>
        <odometrySource>world</odometrySource>
        <publishOdomTF>1</publishOdomTF>
        <robotBaseFrame>base_footprint</robotBaseFrame>
        <publishWheelTF>0</publishWheelTF>
        <publishTf>1</publishTf>
        <publishWheelJointState>1</publishWheelJointState>
        <legacyMode>0</legacyMode>
        <updateRate>30</updateRate>
        <leftJoint>wheel_left_joint</leftJoint>
        <rightJoint>wheel_right_joint</rightJoint>
        <wheelSeparation>0.160</wheelSeparation>
        <wheelDiameter>0.066</wheelDiameter>
        <wheelAcceleration>1</wheelAcceleration>
        <wheelTorque>10</wheelTorque>
        <rosDebugLevel>na</rosDebugLevel>
        <robotNamespace>/turtle_ar/</robotNamespace>
      </plugin>
      <static>0</static>
      <plugin name='imu_plugin' filename='libgazebo_ros_imu.so'>
        <alwaysOn>1</alwaysOn>
        <topicName>imu</topicName>
        <serviceName>imu_service</serviceName>
        <gaussianNoise>0.0</gaussianNoise>
        <updateRate>0</updateRate>
        <imu>
          <noise>
            <type>gaussian</type>
            <rate>
              <mean>0.0</mean>
              <stddev>2e-4</stddev>
              <bias_mean>0.0000075</bias_mean>
              <bias_stddev>0.0000008</bias_stddev>
            </rate>
            <accel>
              <mean>0.0</mean>
              <stddev>1.7e-2</stddev>
              <bias_mean>0.1</bias_mean>
              <bias_stddev>0.001</bias_stddev>
            </accel>
          </noise>
        </imu>
        <robotNamespace>/turtle_ar/</robotNamespace>
        <bodyName>base_footprint</bodyName>
        <frameName>base_footprint</frameName>
        <xyzOffset>0.064 0 -0.156</xyzOffset>
        <rpyOffset>0 -0 0</rpyOffset>
      </plugin>
      <pose frame=''>0.5 0 0 0 -0 0</pose>
    </model>
    <model name='turtle_follower'>
      <link name='base_footprint'>
        <pose frame=''>0 0 0 0 -0 0</pose>
        <inertial>
          <pose frame=''>-0.00429 0 0.030735 0 -0 0</pose>
          <mass>0.944745</mass>
          <inertia>
            <ixx>0.00718012</ixx>
            <ixy>-1.22941e-05</ixy>
            <ixz>0.000576685</ixz>
            <iyy>0.00721922</iyy>
            <iyz>-5.01209e-06</iyz>
            <izz>0.0041396</izz>
          </inertia>
        </inertial>
        <collision name='base_footprint_fixed_joint_lump__base_link_collision'>
          <pose frame=''>-0.032 0 0.08 0 -0 0</pose>
          <geometry>
            <box>
              <size>0.14 0.14 0.143</size>
            </box>
          </geometry>
          <surface>
            <contact>
              <ode/>
            </contact>
            <friction>
              <ode/>
              <torsional>
                <ode/>
              </torsional>
            </friction>
            <bounce/>
          </surface>
          <max_contacts>10</max_contacts>
        </collision>
        <collision name='base_footprint_fixed_joint_lump__camera_link_collision_1'>
          <pose frame=''>0.04 0 0.155 0 -0 0</pose>
          <geometry>
            <box>
              <size>0.01 0.01 0.01</size>
            </box>
          </geometry>
          <surface>
            <contact>
              <ode>
                <kp>100</kp>
                <kd>100</kd>
              </ode>
            </contact>
            <friction>
              <ode>
                <mu>0.1</mu>
                <mu2>0.1</mu2>
                <fdir1>1 0 0</fdir1>
              </ode>
              <torsional>
                <ode/>
              </torsional>
            </friction>
            <bounce/>
          </surface>
          <max_contacts>10</max_contacts>
        </collision>
        <collision name='base_footprint_fixed_joint_lump__caster_back_link_collision_2'>
          <pose frame=''>-0.081 1e-06 0.005 -1.57 0 0</pose>
          <geometry>
            <box>
              <size>0.03 0.009 0.02</size>
            </box>
          </geometry>
          <surface>
            <contact>
              <ode>
                <kp>1e+06</kp>
                <kd>100</kd>
                <max_vel>1</max_vel>
                <min_depth>0.001</min_depth>
              </ode>
            </contact>
            <friction>
              <ode>
                <mu>0.1</mu>
                <mu2>0.1</mu2>
              </ode>
              <torsional>
                <ode/>
              </torsional>
            </friction>
            <bounce/>
          </surface>
          <max_contacts>10</max_contacts>
        </collision>
        <collision name='base_footprint_fixed_joint_lump__base_scan_collision_3'>
          <pose frame=''>-0.017 0 0.1755 0 -0 0</pose>
          <geometry>
            <cylinder>
              <length>0.0315</length>
              <radius>0.055</radius>
            </cylinder>
          </geometry>
          <surface>
            <contact>
              <ode/>
            </contact>
            <friction>
              <ode/>
              <torsional>
                <ode/>
              </torsional>
            </friction>
            <bounce/>
          </surface>
          <max_contacts>10</max_contacts>
        </collision>
        <visual name='base_footprint_fixed_joint_lump__base_link_visual'>
          <pose frame=''>-0.032 0 0.01 0 -0 0</pose>
          <geometry>
            <mesh>
              <scale>0.001 0.001 0.001</scale>
              <uri>/home/kketan20/Workspaces/rsp_project/src/rsp_project/turtlebot3/turtlebot3_description/meshes/bases/burger_base.stl</uri>
            </mesh>
          </geometry>
          <material>
            <script>
              <name>Gazebo/DarkGrey</name>
              <uri>file://media/materials/scripts/gazebo.material</uri>
            </script>
          </material>
        </visual>
        <visual name='base_footprint_fixed_joint_lump__camera_link_visual_1'>
          <pose frame=''>0.04 0 0.155 0 -0 0</pose>
          <geometry>
            <box>
              <size>0.01 0.01 0.01</size>
            </box>
          </geometry>
          <material>
            <script>
              <uri>__default__</uri>
              <name>__default__</name>
            </script>
          </material>
        </visual>
        <visual name='base_footprint_fixed_joint_lump__base_scan_visual_2'>
          <pose frame=''>-0.032 0 0.182 0 -0 0</pose>
          <geometry>
            <mesh>
              <scale>0.001 0.001 0.001</scale>
              <uri>/home/kketan20/Workspaces/rsp_project/src/rsp_project/turtlebot3/turtlebot3_description/meshes/sensors/lds.stl</uri>
            </mesh>
          </geometry>
          <material>
            <script>
              <name>Gazebo/FlatBlack</name>
              <uri>file://media/materials/scripts/gazebo.material</uri>
            </script>
          </material>
        </visual>
        <velocity_decay/>
        <velocity_decay/>
        <sensor name='camer1' type='camera'>
          <update_rate>30</update_rate>
          <camera name='raspicam'>
            <horizontal_fov>1.39626</horizontal_fov>
            <image>
              <width>1920</width>
              <height>1080</height>
              <format>R8G8B8</format>
            </image>
            <clip>
              <near>0.02</near>
              <far>300</far>
            </clip>
            <noise>
              <type>gaussian</type>
              <mean>0</mean>
              <stddev>0.007</stddev>
            </noise>
          </camera>
          <plugin name='camera_plugin' filename='libgazebo_ros_camera.so'>
            <alwaysOn>1</alwaysOn>
            <updateRate>0.0</updateRate>
            <cameraName>raspicam</cameraName>
            <imageTopicName>image_raw</imageTopicName>
            <cameraInfoTopicName>camera_info</cameraInfoTopicName>
            <frameName>camera_link</frameName>
            <hackBaseline>0.07</hackBaseline>
            <distortionK1>0.0</distortionK1>
            <distortionK2>0.0</distortionK2>
            <distortionK3>0.0</distortionK3>
            <distortionT1>0.0</distortionT1>
            <distortionT2>0.0</distortionT2>
            <robotNamespace>/turtle_follower/</robotNamespace>
          </plugin>
          <pose frame=''>0.04 0 0.155 0 -0 0</pose>
        </sensor>
        <velocity_decay/>
        <velocity_decay/>
        <velocity_decay/>
        <sensor name='imu' type='imu'>
          <always_on>1</always_on>
          <visualize>0</visualize>
          <pose frame=''>-0.032 0 0.078 -0.001593 0.001593 3.14159</pose>
          <imu/>
        </sensor>
        <gravity>1</gravity>
        <velocity_decay/>
        <sensor name='lds_lfcd_sensor' type='ray'>
          <visualize>0</visualize>
          <update_rate>5</update_rate>
          <ray>
            <scan>
              <horizontal>
                <samples>360</samples>
                <resolution>1</resolution>
                <min_angle>0</min_angle>
                <max_angle>6.28319</max_angle>
              </horizontal>
              <vertical>
                <samples>1</samples>
                <min_angle>0</min_angle>
                <max_angle>0</max_angle>
              </vertical>
            </scan>
            <range>
              <min>0.12</min>
              <max>3.5</max>
              <resolution>0.015</resolution>
            </range>
            <noise>
              <type>gaussian</type>
              <mean>0</mean>
              <stddev>0.01</stddev>
            </noise>
          </ray>
          <plugin name='gazebo_ros_lds_lfcd_controller' filename='libgazebo_ros_laser.so'>
            <topicName>scan</topicName>
            <frameName>base_scan</frameName>
            <robotNamespace>/turtle_follower/</robotNamespace>
          </plugin>
          <pose frame=''>-0.032 0 0.182 0 -0 0</pose>
        </sensor>
        <self_collide>0</self_collide>
        <enable_wind>0</enable_wind>
        <kinematic>0</kinematic>
      </link>
      <link name='wheel_left_link'>
        <pose frame=''>0 0.08 0.033 -1.57 0 0</pose>
        <inertial>
          <pose frame=''>0 0 0 0 -0 0</pose>
          <mass>0.0284989</mass>
          <inertia>
            <ixx>1.11756e-05</ixx>
            <ixy>-4.23698e-11</ixy>
            <ixz>-5.93817e-09</ixz>
            <iyy>1.11924e-05</iyy>
            <iyz>-1.44001e-11</iyz>
            <izz>2.07126e-05</izz>
          </inertia>
        </inertial>
        <collision name='wheel_left_link_collision'>
          <pose frame=''>0 0 0 0 -0 0</pose>
          <geometry>
            <cylinder>
              <length>0.018</length>
              <radius>0.033</radius>
            </cylinder>
          </geometry>
          <surface>
            <contact>
              <ode>
                <kp>500000</kp>
                <kd>10</kd>
                <max_vel>0.1</max_vel>
                <min_depth>0.001</min_depth>
              </ode>
            </contact>
            <friction>
              <ode>
                <mu>0.1</mu>
                <mu2>0.1</mu2>
                <fdir1>1 0 0</fdir1>
              </ode>
              <torsional>
                <ode/>
              </torsional>
            </friction>
            <bounce/>
          </surface>
          <max_contacts>10</max_contacts>
        </collision>
        <visual name='wheel_left_link_visual'>
          <pose frame=''>0 0 0 1.57 -0 0</pose>
          <geometry>
            <mesh>
              <scale>0.001 0.001 0.001</scale>
              <uri>/home/kketan20/Workspaces/rsp_project/src/rsp_project/turtlebot3/turtlebot3_description/meshes/wheels/left_tire.stl</uri>
            </mesh>
          </geometry>
          <material>
            <script>
              <name>Gazebo/FlatBlack</name>
              <uri>file://media/materials/scripts/gazebo.material</uri>
            </script>
          </material>
        </visual>
        <gravity>1</gravity>
        <velocity_decay/>
        <self_collide>0</self_collide>
        <enable_wind>0</enable_wind>
        <kinematic>0</kinematic>
      </link>
      <joint name='wheel_left_joint' type='revolute'>
        <child>wheel_left_link</child>
        <parent>base_footprint</parent>
        <axis>
          <xyz>0 1 0.000796</xyz>
          <limit>
            <lower>-1e+16</lower>
            <upper>1e+16</upper>
          </limit>
          <dynamics>
            <spring_reference>0</spring_reference>
            <spring_stiffness>0</spring_stiffness>
          </dynamics>
          <use_parent_model_frame>1</use_parent_model_frame>
        </axis>
      </joint>
      <link name='wheel_right_link'>
        <pose frame=''>0 -0.08 0.033 -1.57 0 0</pose>
        <inertial>
          <pose frame=''>0 0 0 0 -0 0</pose>
          <mass>0.0284989</mass>
          <inertia>
            <ixx>1.11756e-05</ixx>
            <ixy>-4.23698e-11</ixy>
            <ixz>-5.93817e-09</ixz>
            <iyy>1.11924e-05</iyy>
            <iyz>-1.44001e-11</iyz>
            <izz>2.07126e-05</izz>
          </inertia>
        </inertial>
        <collision name='wheel_right_link_collision'>
          <pose frame=''>0 0 0 0 -0 0</pose>
          <geometry>
            <cylinder>
              <length>0.018</length>
              <radius>0.033</radius>
            </cylinder>
          </geometry>
          <surface>
            <contact>
              <ode>
                <kp>500000</kp>
                <kd>10</kd>
                <max_vel>0.1</max_vel>
                <min_depth>0.001</min_depth>
              </ode>
            </contact>
            <friction>
              <ode>
                <mu>0.1</mu>
                <mu2>0.1</mu2>
                <fdir1>1 0 0</fdir1>
              </ode>
              <torsional>
                <ode/>
              </torsional>
            </friction>
            <bounce/>
          </surface>
          <max_contacts>10</max_contacts>
        </collision>
        <visual name='wheel_right_link_visual'>
          <pose frame=''>0 0 0 1.57 -0 0</pose>
          <geometry>
            <mesh>
              <scale>0.001 0.001 0.001</scale>
              <uri>/home/kketan20/Workspaces/rsp_project/src/rsp_project/turtlebot3/turtlebot3_description/meshes/wheels/right_tire.stl</uri>
            </mesh>
          </geometry>
          <material>
            <script>
              <name>Gazebo/FlatBlack</name>
              <uri>file://media/materials/scripts/gazebo.material</uri>
            </script>
          </material>
        </visual>
        <gravity>1</gravity>
        <velocity_decay/>
        <self_collide>0</self_collide>
        <enable_wind>0</enable_wind>
        <kinematic>0</kinematic>
      </link>
      <joint name='wheel_right_joint' type='revolute'>
        <child>wheel_right_link</child>
        <parent>base_footprint</parent>
        <axis>
          <xyz>0 1 0.000796</xyz>
          <limit>
            <lower>-1e+16</lower>
            <upper>1e+16</upper>
          </limit>
          <dynamics>
            <spring_reference>0</spring_reference>
            <spring_stiffness>0</spring_stiffness>
          </dynamics>
          <use_parent_model_frame>1</use_parent_model_frame>
        </axis>
      </joint>
      <plugin name='turtlebot3_burger_controller' filename='libgazebo_ros_diff_drive.so'>
        <commandTopic>cmd_vel</commandTopic>
        <odometryTopic>odom</odometryTopic>
        <odometryFrame>odom</odometryFrame>
        <odometrySource>world</odometrySource>
        <publishOdomTF>1</publishOdomTF>
        <robotBaseFrame>base_footprint</robotBaseFrame>
        <publishWheelTF>0</publishWheelTF>
        <publishTf>1</publishTf>
        <publishWheelJointState>1</publishWheelJointState>
        <legacyMode>0</legacyMode>
        <updateRate>30</updateRate>
        <leftJoint>wheel_left_joint</leftJoint>
        <rightJoint>wheel_right_joint</rightJoint>
        <wheelSeparation>0.160</wheelSeparation>
        <wheelDiameter>0.066</wheelDiameter>
        <wheelAcceleration>1</wheelAcceleration>
        <wheelTorque>10</wheelTorque>
        <rosDebugLevel>na</rosDebugLevel>
        <robotNamespace>/turtle_follower/</robotNamespace>
      </plugin>
      <static>0</static>
      <plugin name='imu_plugin' filename='libgazebo_ros_imu.so'>
        <alwaysOn>1</alwaysOn>
        <topicName>imu</topicName>
        <serviceName>imu_service</serviceName>
        <gaussianNoise>0.0</gaussianNoise>
        <updateRate>0</updateRate>
        <imu>
          <noise>
            <type>gaussian</type>
            <rate>
              <mean>0.0</mean>
              <stddev>2e-4</stddev>
              <bias_mean>0.0000075</bias_mean>
              <bias_stddev>0.0000008</bias_stddev>
            </rate>
            <accel>
              <mean>0.0</mean>
              <stddev>1.7e-2</stddev>
              <bias_mean>0.1</bias_mean>
              <bias_stddev>0.001</bias_stddev>
            </accel>
          </noise>
        </imu>
        <robotNamespace>/turtle_follower/</robotNamespace>
        <bodyName>base_footprint</bodyName>
        <frameName>base_footprint</frameName>
        <xyzOffset>0.000108341 0.000108381 -0.156051</xyzOffset>
        <rpyOffset>-4.66303e-07 5.19476e-07 -0.00094028</rpyOffset>
      </plugin>
      <pose frame=''>0 0 0 0 -0 0</pose>
    </model>
    <light name='user_directional_light_0' type='directional'>
      <pose frame=''>-1.18033 1.56823 1 0 -0 0</pose>
      <diffuse>0.5 0.5 0.5 1</diffuse>
      <specular>0.1 0.1 0.1 1</specular>
      <direction>0.1 0.1 -0.9</direction>
      <attenuation>
        <range>20</range>
        <constant>0.5</constant>
        <linear>0.01</linear>
        <quadratic>0.001</quadratic>
      </attenuation>
      <cast_shadows>1</cast_shadows>
    </light>
    <light name='user_directional_light_1' type='directional'>
      <pose frame=''>-3.99824 2.50068 1 0 -0 0</pose>
      <diffuse>0.5 0.5 0.5 1</diffuse>
      <specular>0.1 0.1 0.1 1</specular>
      <direction>0.1 0.1 -0.9</direction>
      <attenuation>
        <range>20</range>
        <constant>0.5</constant>
        <linear>0.01</linear>
        <quadratic>0.001</quadratic>
      </attenuation>
      <cast_shadows>1</cast_shadows>
    </light>
    <light name='user_directional_light_2' type='directional'>
      <pose frame=''>0.567817 -0.547989 1 0 -0 0</pose>
      <diffuse>0.5 0.5 0.5 1</diffuse>
      <specular>0.1 0.1 0.1 1</specular>
      <direction>0.1 0.1 -0.9</direction>
      <attenuation>
        <range>20</range>
        <constant>0.5</constant>
        <linear>0.01</linear>
        <quadratic>0.001</quadratic>
      </attenuation>
      <cast_shadows>1</cast_shadows>
    </light>
    <light name='user_directional_light_3' type='directional'>
      <pose frame=''>-1.92813 5.21908 1 0 -0 0</pose>
      <diffuse>0.5 0.5 0.5 1</diffuse>
      <specular>0.1 0.1 0.1 1</specular>
      <direction>0.1 0.1 -0.9</direction>
      <attenuation>
        <range>20</range>
        <constant>0.5</constant>
        <linear>0.01</linear>
        <quadratic>0.001</quadratic>
      </attenuation>
      <cast_shadows>1</cast_shadows>
    </light>
    <light name='user_directional_light_4' type='directional'>
      <pose frame=''>-3.55909 1.3059 1 0 -0 0</pose>
      <diffuse>0.5 0.5 0.5 1</diffuse>
      <specular>0.1 0.1 0.1 1</specular>
      <direction>0.1 0.1 -0.9</direction>
      <attenuation>
        <range>20</range>
        <constant>0.5</constant>
        <linear>0.01</linear>
        <quadratic>0.001</quadratic>
      </attenuation>
      <cast_shadows>1</cast_shadows>
    </light>
    <state world_name='default'>
      <sim_time>45 859000000</sim_time>
      <real_time>90 335628277</real_time>
      <wall_time>1652340026 526521373</wall_time>
      <iterations>45859</iterations>
      <model name='ground_plane'>
        <pose frame=''>0 0 0 0 -0 0</pose>
        <scale>1 1 1</scale>
        <link name='link'>
          <pose frame=''>0 0 0 0 -0 0</pose>
          <velocity>0 0 0 0 -0 0</velocity>
          <acceleration>0 0 0 0 -0 0</acceleration>
          <wrench>0 0 0 0 -0 0</wrench>
        </link>
      </model>
      <model name='turtle_ar'>
        <pose frame=''>0.499784 0.000887 -0.001002 -1.6e-05 0.007692 0.013596</pose>
        <scale>1 1 1</scale>
        <link name='base_footprint'>
          <pose frame=''>0.499784 0.000887 -0.001002 -1.6e-05 0.007692 0.013596</pose>
          <velocity>-4e-06 2.2e-05 3.7e-05 4.1e-05 -0.000115 0.000336</velocity>
          <acceleration>-0 0 -0 0 -0 0</acceleration>
          <wrench>-0 0 -0 0 -0 0</wrench>
        </link>
        <link name='wheel_left_link'>
          <pose frame=''>0.49895 0.080881 0.031996 -1.57018 -0.024965 0.013577</pose>
          <velocity>-3.4e-05 2e-05 4.1e-05 1.6e-05 -0.000897 0.000338</velocity>
          <acceleration>-0 0 -0 0 -1e-06 1e-06</acceleration>
          <wrench>-0 0 -0 0 -0 0</wrench>
        </link>
        <link name='wheel_right_link'>
          <pose frame=''>0.501126 -0.079104 0.031998 -1.57018 0.040007 0.013614</pose>
          <velocity>1.9e-05 2.1e-05 3.4e-05 -2e-06 0.000648 0.000335</velocity>
          <acceleration>0 0 -0 0 1e-06 1e-06</acceleration>
          <wrench>0 0 -0 0 -0 0</wrench>
        </link>
      </model>
      <model name='turtle_follower'>
        <pose frame=''>-1.02831 4e-06 -0.001003 -1.5e-05 0.007724 0.000161</pose>
        <scale>1 1 1</scale>
        <link name='base_footprint'>
          <pose frame=''>-1.02831 4e-06 -0.001003 -1.5e-05 0.007724 0.000161</pose>
          <velocity>-0.025101 2.2e-05 3.4e-05 3.7e-05 -0.000161 0.000344</velocity>
          <acceleration>-0.000633 -6e-06 -5e-06 -1.1e-05 8.1e-05 -9.6e-05</acceleration>
          <wrench>-0.000598 -6e-06 -5e-06 0 -0 0</wrench>
        </link>
        <link name='wheel_left_link'>
          <pose frame=''>-1.02807 0.080003 0.031995 -1.57018 -0.271501 -2e-06</pose>
          <velocity>-0.025135 2.1e-05 3.9e-05 7.3e-05 -0.761305 -0.000137</velocity>
          <acceleration>-0.000632 -7e-06 -8e-06 0.000133 -0.009885 -0.000477</acceleration>
          <wrench>-1.8e-05 -0 -0 0 -0 0</wrench>
        </link>
        <link name='wheel_right_link'>
          <pose frame=''>-1.02804 -0.079997 0.031998 -1.57017 -0.25655 3e-06</pose>
          <velocity>-0.02508 2e-05 3.2e-05 8.2e-05 -0.75976 -0.000146</velocity>
          <acceleration>-0.000645 -6e-06 -5e-06 0.000139 -0.010181 -0.000396</acceleration>
          <wrench>-1.8e-05 -0 -0 0 -0 0</wrench>
        </link>
      </model>
      <light name='sun'>
        <pose frame=''>0 0 10 0 -0 0</pose>
      </light>
      <light name='user_directional_light_0'>
        <pose frame=''>-1.18033 1.56823 1 0 -0 0</pose>
      </light>
      <light name='user_directional_light_1'>
        <pose frame=''>-3.99824 2.50068 1 0 -0 0</pose>
      </light>
      <light name='user_directional_light_2'>
        <pose frame=''>0.567817 -0.547989 1 0 -0 0</pose>
      </light>
      <light name='user_directional_light_3'>
        <pose frame=''>-1.92813 5.21908 1 0 -0 0</pose>
      </light>
      <light name='user_directional_light_4'>
        <pose frame=''>-3.55909 1.3059 1 0 -0 0</pose>
      </light>
    </state>
    <gui fullscreen='0'>
      <camera name='user_camera'>
        <pose frame=''>5 -5 2 0 0.275643 2.35619</pose>
        <view_controller>orbit</view_controller>
        <projection_type>perspective</projection_type>
      </camera>
    </gui>
  </world>
</sdf>
